[2010-09-12 21:28:36,945] [ERROR] from snc.__init__ at snc.py:52 :
SSLError: SSLError(336265218, '_ssl.c:337: error:140B0002:SSL routines:SSL_CTX_use_PrivateKey_file:system lib')
[2010-09-12 21:29:35,612] [ERROR] from snc.__init__ at snc.py:52 :
SSLError: SSLError(1, '_ssl.c:480: error:14094418:SSL routines:SSL3_READ_BYTES:tlsv1 alert unknown ca')
[2010-09-12 21:30:31,872] [ERROR] from snc.write_all at snc.py:99 :
socket error: error(32, 'Broken pipe')
[2010-09-12 21:30:31,876] [ERROR] from snc.close at snc.py:139 :
socket error: error(11, 'Resource temporarily unavailable')
[2010-09-13 16:44:09,263] [ERROR] from snc.close at snc.py:136 :
SSLError: SSLError(2, '_ssl.c:1357: The operation did not complete (read)')
[2010-09-14 11:09:35,780] [ERROR] from snc.close at snc.py:136 :
SSLError: SSLError(2, '_ssl.c:1357: The operation did not complete (read)')
[2010-09-19 17:37:34,551] [ERROR] from close in snc at snc.py:137 :
SSLError: SSLError(2, '_ssl.c:1357: The operation did not complete (read)')

[2010-09-19 17:38:07,758] [ERROR] from write_all in snc at snc.py:99 :
socket error: error(104, 'Connection reset by peer')

[2010-09-19 17:38:07,758] [WARNING] from send in filetrans at filetrans.py:118 :
failed to transfer file because of network error.

[2010-09-19 17:38:07,767] [ERROR] from close in snc at snc.py:139 :
socket error: error(11, 'Resource temporarily unavailable')

[2010-09-20 10:43:36,376] [ERROR] from read_all in snc at snc.py:81 :
socket error: SSLError(2, '_ssl.c:1325: The operation did not complete (read)')

[2010-09-20 10:43:36,382] [ERROR] from close in snc at snc.py:136 :
SSLError: SSLError(2, '_ssl.c:1357: The operation did not complete (read)')

[2010-09-20 10:44:17,614] [ERROR] from read_all in snc at snc.py:81 :
socket error: SSLError(2, '_ssl.c:1325: The operation did not complete (read)')

[2010-09-20 10:44:17,618] [ERROR] from close in snc at snc.py:136 :
SSLError: SSLError(2, '_ssl.c:1357: The operation did not complete (read)')

[2010-09-21 17:27:34,761] [ERROR] from __init__ in snc at snc.py:47 :
socket error: error('failed to connect',)

[2010-09-21 17:28:47,290] [ERROR] from __init__ in snc at snc.py:74 :
failed to establish SSL connection:
TypeError('snc() argument 1 must be snc.socket, not instance',)

[2010-09-21 17:34:37,684] [ERROR] from __init__ in snc at snc.py:74 :
failed to establish SSL connection:
TypeError('snc() argument 1 must be snc.socket, not instance',)

[2010-09-21 17:35:38,341] [ERROR] from __init__ in snc at snc.py:74 :
failed to establish SSL connection:
TypeError('snc() argument 1 must be snc.socket, not instance',)

[2010-09-21 17:35:50,285] [ERROR] from __init__ in snc at snc.py:74 :
failed to establish SSL connection:
TypeError('snc() argument 1 must be snc.socket, not instance',)

[2010-09-21 17:36:09,389] [ERROR] from __init__ in snc at snc.py:74 :
failed to establish SSL connection:
TypeError('snc() argument 1 must be snc.socket, not instance',)

[2010-09-21 17:36:22,438] [ERROR] from __init__ in snc at snc.py:74 :
failed to establish SSL connection:
TypeError('snc() argument 1 must be snc.socket, not instance',)

[2010-09-21 17:36:39,630] [ERROR] from __init__ in snc at snc.py:74 :
failed to establish SSL connection:
TypeError('snc() argument 1 must be snc.socket, not instance',)

[2010-09-21 17:36:50,230] [ERROR] from __init__ in snc at snc.py:74 :
failed to establish SSL connection:
TypeError('snc() argument 1 must be snc.socket, not instance',)

[2010-09-21 17:40:10,514] [ERROR] from __init__ in snc at snc.py:74 :
failed to establish SSL connection:
TypeError('snc() argument 1 must be snc.socket, not instance',)

[2010-09-21 17:40:38,804] [ERROR] from __init__ in snc at snc.py:74 :
failed to establish SSL connection:
TypeError('snc() argument 1 must be snc.socket, not instance',)

[2010-09-21 17:40:53,756] [ERROR] from __init__ in snc at snc.py:74 :
failed to establish SSL connection:
TypeError('snc() argument 1 must be snc.socket, not instance',)

[2010-09-21 17:41:27,043] [ERROR] from __init__ in snc at snc.py:74 :
failed to establish SSL connection:
TypeError('snc() argument 1 must be snc.socket, not instance',)

[2010-09-21 17:42:44,830] [ERROR] from __init__ in snc at snc.py:74 :
failed to establish SSL connection:
TypeError('snc() argument 1 must be snc.socket, not instance',)

[2010-09-21 18:16:55,004] [ERROR] from __init__ in snc at snc.py:74 :
failed to establish SSL connection:
TypeError('snc() argument 1 must be snc.socket, not instance',)

[2010-09-21 18:20:35,967] [ERROR] from __init__ in snc at snc.py:74 :
failed to establish SSL connection:
TypeError('snc() argument 1 must be snc.socket, not instance',)

[2010-09-21 18:28:12,528] [ERROR] from __init__ in snc at snc.py:51 :
socket error: error('failed to connect',)

[2010-09-21 18:29:25,649] [ERROR] from __init__ in snc at snc.py:52 :
socket error: error('failed to connect',)

[2010-09-21 18:29:44,318] [ERROR] from write in snc at snc.py:116 :
failed to write:
TypeError('an integer is required',)

[2010-09-21 18:30:46,591] [ERROR] from write in snc at snc.py:116 :
failed to write:
TypeError('write() argument 1 must be string or buffer, not builtin_function_or_method',)

[2010-09-21 18:31:27,199] [ERROR] from write in snc at snc.py:116 :
failed to write:
error('SSL error [func SSL_write] [errno Resource temporarily unavailable]: error:00000003:lib(0):func(0):BN lib',)

[2010-09-21 18:33:12,855] [ERROR] from write in snc at snc.py:116 :
failed to write:
error('SSL error [func SSL_write] [errno Resource temporarily unavailable]: error:00000003:lib(0):func(0):BN lib',)

[2010-09-21 18:38:56,837] [ERROR] from write in snc at snc.py:115 :
failed to write:
error('SSL error [func SSL_write] [errno Broken pipe]: error:00000005:lib(0):func(0):DH lib',)

[2010-09-22 10:03:01,953] [ERROR] from socket in snc at snc.py:48 :
socket error: error('failed to connect',)

[2010-09-22 10:03:28,608] [ERROR] from read in snc at snc.py:110 :
failed to read:
error('SSL error [func SSL_read] [errno: Success]: error:00000006:lib(0):func(0):EVP lib',)

[2010-09-23 12:00:36,635] [ERROR] from socket in snc at snc.py:52 :
socket error: error('failed to connect',)

